---
title: Rust panic
date: 2021-09-26 15:37
modify: 星期日 26日 九月 2021 15:37:40
author: edony.zpc
tags: 001-computer-technology
---

# Rust panic
Rust 有 `panic!`宏，当执行这个宏时，程序会打印出一个错误信息，展开并清理栈数据，然后接着退出。出现这种情况的场景通常是检测到一些类型的 bug，而且程序员并不清楚该如何处理它。

```rust
// src/main.rs
fn main() {
    let v = vec![1, 2, 3];

    v[99];
}

// cargo run result
$ RUST_BACKTRACE=1 cargo run
    Finished dev [unoptimized + debuginfo] target(s) in 0.00s
     Running `target/debug/panic`
thread 'main' panicked at 'index out of bounds: the len is 3 but the index is 99', libcore/slice/mod.rs:2448:10
stack backtrace:
   0: std::sys::unix::backtrace::tracing::imp::unwind_backtrace
             at libstd/sys/unix/backtrace/tracing/gcc_s.rs:49
   1: std::sys_common::backtrace::print
             at libstd/sys_common/backtrace.rs:71
             at libstd/sys_common/backtrace.rs:59
   2: std::panicking::default_hook::{{closure}}
             at libstd/panicking.rs:211
   3: std::panicking::default_hook
             at libstd/panicking.rs:227
   4: <std::panicking::begin_panic::PanicPayload<A> as core::panic::BoxMeUp>::get
             at libstd/panicking.rs:476
   5: std::panicking::continue_panic_fmt
             at libstd/panicking.rs:390
   6: std::panicking::try::do_call
             at libstd/panicking.rs:325
   7: core::ptr::drop_in_place
             at libcore/panicking.rs:77
   8: core::ptr::drop_in_place
             at libcore/panicking.rs:59
   9: <usize as core::slice::SliceIndex<[T]>>::index
             at libcore/slice/mod.rs:2448
  10: core::slice::<impl core::ops::index::Index<I> for [T]>::index
             at libcore/slice/mod.rs:2316
  11: <alloc::vec::Vec<T> as core::ops::index::Index<I>>::index
             at liballoc/vec.rs:1653
  12: panic::main
             at src/main.rs:4
  13: std::rt::lang_start::{{closure}}
             at libstd/rt.rs:74
  14: std::panicking::try::do_call
             at libstd/rt.rs:59
             at libstd/panicking.rs:310
  15: macho_symbol_search
             at libpanic_unwind/lib.rs:102
  16: std::alloc::default_alloc_error_hook
             at libstd/panicking.rs:289
             at libstd/panic.rs:392
             at libstd/rt.rs:58
  17: std::rt::lang_start
             at libstd/rt.rs:74
  18: panic::main

```
## References
1. [panic! 与不可恢复的错误](https://kaisery.github.io/trpl-zh-cn/ch09-01-unrecoverable-errors-with-panic.html)